No CUDA runtime is found, using CUDA_HOME='/usr/local/cuda'

[0;32m[VAIQ_NOTE]: Loading NNDCT kernels...[0m
Net(
  (cnn_layers): Sequential(
    (0): Conv2d(2, 24, kernel_size=(2, 2), stride=(1, 1))
    (1): BatchNorm2d(24, eps=1e-05, momentum=0.1, affine=True, track_running_stats=True)
    (2): CELU(alpha=1.0)
    (3): Conv2d(24, 38, kernel_size=(2, 2), stride=(1, 1))
    (4): BatchNorm2d(38, eps=1e-05, momentum=0.1, affine=True, track_running_stats=True)
    (5): CELU(alpha=1.0)
    (6): Conv2d(38, 66, kernel_size=(2, 2), stride=(1, 1))
    (7): BatchNorm2d(66, eps=1e-05, momentum=0.1, affine=True, track_running_stats=True)
    (8): CELU(alpha=1.0)
  )
  (linear_layers): Sequential(
    (0): Linear(in_features=264, out_features=60, bias=True)
    (1): BatchNorm1d(60, eps=1e-05, momentum=0.1, affine=True, track_running_stats=True)
    (2): CELU(alpha=1.0)
    (3): Linear(in_features=60, out_features=8, bias=True)
    (4): BatchNorm1d(8, eps=1e-05, momentum=0.1, affine=True, track_running_stats=True)
    (5): CELU(alpha=1.0)
    (6): Linear(in_features=8, out_features=8, bias=False)
  )
)
QUANT_MODE:  test
RAND_IN:  tensor([[[[ 7.0908e-01, -4.1686e-01,  6.1266e-01, -9.1387e-01,  7.0461e-01,
            5.8402e-01, -1.3654e+00, -3.4597e-01,  6.9457e-01,  1.0631e+00,
            3.2458e-02,  4.1105e-01, -6.4402e-01, -1.8186e+00,  3.7203e-01,
            3.4225e-02, -1.2160e+00,  6.3706e-01,  1.1193e+00, -2.1217e+00,
           -4.0678e-01,  1.3788e-01,  6.5285e-01,  5.3194e-01, -5.6009e-01],
          [ 8.3638e-01, -1.8170e+00,  1.8529e+00,  3.4788e-01,  8.6832e-02,
           -1.1097e+00, -8.1759e-01, -5.0239e-01, -9.1787e-01,  1.9233e+00,
            1.6508e+00,  7.6123e-01,  1.9563e-01, -1.5978e+00, -1.5796e+00,
           -7.7338e-01, -5.2950e-01, -2.4995e-01,  7.4463e-01,  2.1131e-01,
           -1.9709e+00, -4.5836e-01,  5.6776e-01, -9.5522e-02, -1.6787e-01]],

         [[-8.2168e-01, -1.1809e+00, -4.0615e-01,  2.2010e+00, -1.5557e+00,
            4.3483e-01,  5.5252e-01,  1.6323e+00,  8.3307e-01, -1.1234e+00,
            4.8213e-01,  6.0968e-01, -1.5137e-01, -3.0363e-01,  7.8063e-01,
           -9.2791e-01, -2.1974e-03,  2.6361e-01,  1.7904e+00, -1.1015e-01,
           -1.4015e+00, -1.7290e+00,  4.4342e-01, -4.6851e-01, -8.1447e-01],
          [-3.6473e-01,  8.0142e-01,  7.2075e-01, -1.1136e+00, -1.8885e-01,
            1.6424e+00,  9.5077e-01,  4.6086e-01, -1.1238e+00,  1.3593e+00,
            7.2967e-01, -1.3061e+00,  1.2318e+00,  4.9962e-01,  6.2530e-02,
            1.7090e+00,  5.4950e-01,  8.5228e-01, -6.5182e-01, -1.3081e+00,
           -1.2662e+00,  3.1227e-01,  4.8080e-01, -9.1723e-01, -7.1696e-02]]]])
RAND_IN SHAPE:  torch.Size([1, 2, 2, 25])
QUANT_MODEL:  quant_model

[0;33m[VAIQ_WARN]: CUDA is not available, change device to CPU[0m

[0;32m[VAIQ_NOTE]: Quantization test process start up...[0m
Traceback (most recent call last):
  File "quantize.py", line 136, in <module>
    run_main()
  File "quantize.py", line 130, in run_main
    args.quant_mode, args.batchsize, args.quant_model, torch.device('cpu'))
  File "quantize.py", line 52, in quantize
    quantizer = torch_quantizer(quant_mode, model, (rand_in), output_dir=quant_model)
  File "/opt/vitis_ai/conda/envs/vitis-ai-pytorch/lib/python3.6/site-packages/pytorch_nndct/apis.py", line 77, in __init__
    custom_quant_ops = custom_quant_ops)
  File "/opt/vitis_ai/conda/envs/vitis-ai-pytorch/lib/python3.6/site-packages/pytorch_nndct/qproc/base.py", line 108, in __init__
    quant_strategy)
  File "/opt/vitis_ai/conda/envs/vitis-ai-pytorch/lib/python3.6/site-packages/pytorch_nndct/qproc/base.py", line 74, in _init_quant_env
    quant_strategy)
  File "/opt/vitis_ai/conda/envs/vitis-ai-pytorch/lib/python3.6/site-packages/nndct_shared/quantization/base_quantizer.py", line 61, in create_from_strategy
    quant_strategy.mix_bit)
  File "/opt/vitis_ai/conda/envs/vitis-ai-pytorch/lib/python3.6/site-packages/pytorch_nndct/quantization/torchquantizer.py", line 56, in __init__
    self.bias_corr = torch.load(self.bias_corr_file)
  File "/opt/vitis_ai/conda/envs/vitis-ai-pytorch/lib/python3.6/site-packages/torch/serialization.py", line 525, in load
    with _open_file_like(f, 'rb') as opened_file:
  File "/opt/vitis_ai/conda/envs/vitis-ai-pytorch/lib/python3.6/site-packages/torch/serialization.py", line 212, in _open_file_like
    return _open_file(name_or_buffer, mode)
  File "/opt/vitis_ai/conda/envs/vitis-ai-pytorch/lib/python3.6/site-packages/torch/serialization.py", line 193, in __init__
    super(_open_file, self).__init__(open(name, mode))
FileNotFoundError: [Errno 2] No such file or directory: 'quant_model/bias_corr.pth'
